Workbook

Sheet 18
A1: DANH SÁCH THI VÀ KẾT QUẢ THI IELTS ĐẦU RA
A2: Mã lớp: 18
A3: Đơn vị đào tạo: CÔNG TY CỔ PHẦN TRUNG TÂM ANH NGỮ AMA VINH
A5: TT | B5: Mã HV | C5: HỌ VÀ TÊN | D5: Ho va ten | E5: NĂM SINH | F5: BẬC DẠY | G5: ĐƠN VỊ CÔNG TÁC | H5: PHƯỜNG/XÃ | I5: Số CCCD/ Hộ chiếu | J5: Mã ngạch viên chức | K5: Điểm IELTS đầu vào | L5: Điểm IELTS đầu ra cần đạt | M5: Kết quả thi IELTS đầu ra | N5: Column1 | O5: Column2 | P5: Column3 | Q5: Column4 | R5: KẾT QUẢ (Đạt/Không đạt)
A6: 1 | B6: 341 | C6: Trần Thị Thu Hiền | D6: TRAN THI THU HIEN | E6: 1977 | F6: THPT | G6: Tam Đồng | H6: Phúc Thịnh | I6: 1177043501 | J6: Giáo viên trung học cơ sở hạng II - V.07.04.31 | K6: 4.5
A7: 2 | B7: 342 | C7: Nguyễn Thị Thảo | D7: NGUYEN THI THAO | E7: 1976 | F7: THCS | G7: THCS Tam Đồng | H7: Tiến Thắng | I7: =Merge18!I3 -> 001176040670 | J7: =Merge18!J3 -> Giáo viên trung học cơ sở hạng II - V.07.04.31 | K7: 4.5
A8: 3 | B8: 343 | C8: Bui Mai Lan | D8: BUI MAI LAN | E8: 1977 | F8: THCS | G8: THCS Tiến Thắng | H8: Tiến Thắng | I8: =Merge18!I4 -> 025177005125 | J8: =Merge18!J4 -> V07.04.11 | K8: 4.5
A9: 4 | B9: 344 | C9: Vũ Hùng Quang | D9: VU HUNG QUANG | E9: 1975 | F9: THCS | G9: THCS Tráng Việt | H9: Mê Linh | I9: =Merge18!I5 -> 001075011375 | J9: =Merge18!J5 -> Giáo viên trung học cơ sở hạng II - V.07.04.31 | K9: 4.5
A10: 5 | B10: 345 | C10: Phùng Thị Kim Thao | D10: PHUNG THI KIM THAO | E10: 1977 | F10: THCS | G10: THCS Phạm Hồng Thái | H10: Mê Linh | I10: =Merge18!I6 -> 001177009537 | J10: =Merge18!J6 -> Giáo viên trung học cơ sở hạng III - V.07.04.32 | K10: 4
A11: 6 | B11: 4 | C11: Trần Thị Thanh Tâm | D11: TRAN THI THANH TAM | E11: 1983 | F11: TH | G11: TH Xuân Canh | H11: Đông Anh | I11: =Merge18!I7 -> 026183003026-E032337481 | J11: =Merge18!J7 -> Giáo viên tiểu học hạng II – V.07.03.28 | K11: 4.5
A12: 7 | B12: 347 | C12: Ngô Thị Hồng Dương | D12: NGO THI HONG DUONG | E12: 1975 | F12: THCS | G12: THCS Kim Hoa | H12: Quang Minh | I12: =Merge18!I8 -> 001175030348 | J12: =Merge18!J8 -> Giáo viên trung học cơ sở hạng II - V.07.04.31 | K12: 4.5
A13: 8 | B13: 348 | C13: Ngô Thị Thanh Thuỷ | D13: NGO THI THANH THUY | E13: 1977 | F13: TH | G13: TH Kim Hoa A | H13: Quang Minh | I13: =Merge18!I9 -> 001177032960 | J13: =Merge18!J9 -> Giáo viên tiểu học hạng II – V.07.03.28 | K13: 4.5
A14: 9 | B14: 349 | C14: Nguyễn Thị Yến | D14: NGUYEN THI YEN | E14: 1975 | F14: THCS | G14: THCS Hồng Kỳ | H14: Trung Giã | I14: =Merge18!I10 -> 001175014156 | J14: =Merge18!J10 -> Giáo viên trung học cơ sở hạng II - V.07.04.31 | K14: 4.5
A15: 10 | B15: 350 | C15: Nguyễn Thị Hồng Vân | D15: NGUYEN THI HONG VAN | E15: 1976 | F15: THCS | G15: THCS Trung Giã | H15: Trung Giã | I15: =Merge18!I11 -> 001176048717 | J15: =Merge18!J11 -> Giáo viên trung học cơ sở hạng III - V.07.04.32 | K15: 4.5
A16: 11 | B16: 351 | C16: Nguyễn Thị Mai | D16: NGUYEN THI MAI | E16: 1975 | F16: THCS | G16: THCS Nguyễn Du | H16: Sóc Sơn | K16: 4.5
A17: 12 | B17: 352 | C17: Vương Thị Hạnh | D17: VUONG THI HANH | E17: 1984 | F17: THCS | G17: THCS Tân Minh A | H17: Sóc Sơn | I17: 1184022018 | J17: Giáo viên trung học cơ sở hạng III - V.07.04.32 | K17: 4.5
A18: 13 | B18: 353 | C18: Trịnh Thị Lê Hằng | D18: TRINH THI LE HANG | E18: 1976 | F18: THCS | G18: THCS Tân Minh A | H18: Sóc Sơn | I18: =Merge18!I14 -> 001184022018 | J18: =Merge18!J14 -> Giáo viên trung học cơ sở hạng III - V.07.04.32 | K18: 4.5
A19: 14 | B19: 354 | C19: Lê Đức Vĩnh | D19: LE DUC VINH | E19: 1974 | F19: THCS | G19: THCS Phù Linh | H19: Sóc Sơn | I19: 1074022571 | J19: Giáo viên trung học cơ sở hạng II - V.07.04.31 | K19: 4.5
A20: 15 | B20: 355 | C20: Lê Thị Duyên | D20: LE THI DUYEN | E20: 1984 | F20: TH | G20: TH Đào Duy Tùng | H20: Đông Anh | I20: 1184030240 | J20: Giáo viên tiểu học hạng III – V.07.03.29 | K20: 5
A21: 16 | B21: 356 | C21: Vương Phương Lâm | D21: VUONG PHUONG LAM | E21: 1980 | F21: TH | G21: TH Đại Mạch | H21: Thiên Lộc | I21: 1180014694 | J21: Giáo viên tiểu học hạng III – V.07.03.29 | K21: 5
A22: 17 | B22: 357 | C22: Vũ Thị Mẫn | D22: VU THI MAN | E22: 1980 | F22: TH | G22: TH Lê Hữu Tựu | H22: Phúc Thịnh | I22: 1180005662 | J22: Giáo viên tiểu học hạng III – V.07.03.29 | K22: 5
A23: 18 | B23: 358 | C23: Nguyễn Thị Bích Loan | D23: NGUYEN THI BICH LOAN | E23: 1977 | F23: TH | G23: TH Hải Bối | H23: Vĩnh Thanh | I23: =Merge18!I19 -> 001180005662 | J23: =Merge18!J19 -> Giáo viên tiểu học hạng III – V.07.03.29 | K23: 5
A24: 19 | B24: 359 | C24: Nguyễn Tư Vinh | D24: NGUYEN TU VINH | E24: 1977 | F24: THCS | G24: THCS Liên Hà | H24: Thư Lâm | I24: 27177000344 | J24: Giáo viên trung học cơ sở hạng II - V.07.04.31 | K24: 5
A25: 20 | B25: 360 | C25: Dương Thị Thanh Hương | D25: DUONG THI THANH HUONG | E25: 1976 | F25: THCS | G25: THCS Liên Hà | H25: Thư Lâm | I25: 1176045858 | J25: Giáo viên trung học cơ sở hạng II - V.07.04.31 | K25: 5
M26: Nghe | N26: Đọc | O26: Viết | P26: Nói | Q26: Điểm IELTS đầu ra
F27: SỞ GIÁO DỤC & ĐÀO TẠO HÀ NỘI | N27: ĐẠI DIỆN ĐƠN VỊ ĐÀO TẠO
A28: Số học viên đã thi và được cấp chứng chỉ:
A29: Số học viên đạt kết quả đầu ra:
A30: Số học viên không đạt kết quả đầu ra:
A31: Số học viên thuộc diện bất khả kháng
A32: Số học viên được thanh toán:

Sheet 19
A1: DANH SÁCH THI VÀ KẾT QUẢ THI IELTS ĐẦU RA
A2: Mã lớp: 19
A3: Đơn vị đào tạo: CÔNG TY CỔ PHẦN TRUNG TÂM ANH NGỮ AMA VINH
A5: TT | B5: Mã HV | C5: HỌ VÀ TÊN | D5: Ho va ten | E5: NĂM SINH | F5: BẬC DẠY | G5: ĐƠN VỊ CÔNG TÁC | H5: PHƯỜNG/XÃ | I5: Số CCCD/ Hộ chiếu | J5: Mã ngạch viên chức | K5: Điểm IELTS đầu vào | L5: Điểm IELTS đầu ra cần đạt | M5: Kết quả thi IELTS đầu ra | R5: KẾT QUẢ (Đạt/Không đạt)
M6: Nghe | N6: Đọc | O6: Viết | P6: Nói | Q6: Điểm IELTS đầu ra
A7: Column1 | B7: Column2 | C7: Column3 | D7: Column32 | E7: Column4 | F7: Column5 | G7: Column6 | H7: Column7 | I7: Column8 | J7: Column9 | K7: Column10 | L7: Column11 | M7: Column12 | N7: Column13 | O7: Column14 | P7: Column15 | Q7: Column16 | R7: Column17
A8: 1 | B8: 361 | C8: Phạm Thị Cửu | D8: PHAM THI CUU | E8: 1976 | F8: THCS | G8: THCS Xuân Nộn | H8: Thư Lâm | I8: =IF(ISBLANK(Merge19!T2), IF(ISBLANK(Merge19!U2), "", Merge19!U2),Merge19!T2& IF(ISBLANK(Merge19!U2), "", "-"&Merge19!U2)) -> 001176046134 | J8: =IF(ISBLANK(Merge19!S2),"",Merge19!S2) -> Giáo viên trung học cơ sở hạng II - V.07.04.31 | K8: 5
A9: 2 | B9: 362 | C9: Hoàng Thu Hằng | D9: HOANG THU HANG | E9: 1975 | F9: THCS | G9: THCS Uy Nỗ | H9: Đông Anh | I9: =IF(ISBLANK(Merge19!T3), IF(ISBLANK(Merge19!U3), "", Merge19!U3),Merge19!T3& IF(ISBLANK(Merge19!U3), "", "-"&Merge19!U3)) -> 001178029456 | J9: =IF(ISBLANK(Merge19!S3),"",Merge19!S3) -> Giáo viên trung học phổ thông hạng III - V.07.05.15 | K9: 5
A10: 3 | B10: 363 | C10: Ngô Thị Hà | D10: NGO THI HA | E10: 1975 | F10: THCS | G10: THCS Vân Hà | H10: Thư Lâm | I10: =IF(ISBLANK(Merge19!T4), IF(ISBLANK(Merge19!U4), "", Merge19!U4),Merge19!T4& IF(ISBLANK(Merge19!U4), "", "-"&Merge19!U4)) -> 035185004411 | J10: =IF(ISBLANK(Merge19!S4),"",Merge19!S4) -> Giáo viên trung học phổ thông hạng II - V.07.05.14 | K10: 5
A11: 4 | B11: 364 | C11: Nghiêm Thị Nụ | D11: NGHIEM THI NU | E11: 1984 | F11: THPT | G11: THPT Liên Hà | H11: Thư Lâm | I11: =IF(ISBLANK(Merge19!T5), IF(ISBLANK(Merge19!U5), "", Merge19!U5),Merge19!T5& IF(ISBLANK(Merge19!U5), "", "-"&Merge19!U5)) -> 034178005875 | J11: =IF(ISBLANK(Merge19!S5),"",Merge19!S5) -> Giáo viên tiểu học hạng II – V.07.03.28 | K11: 5
A12: 5 | B12: 365 | C12: Phạm Thị Thu Thiêm | D12: PHAM THI THU THIEM | E12: 1976 | F12: THPT | G12: THPT Liên Hà | H12: Thư Lâm | I12: =IF(ISBLANK(Merge19!T6), IF(ISBLANK(Merge19!U6), "", Merge19!U6),Merge19!T6& IF(ISBLANK(Merge19!U6), "", "-"&Merge19!U6)) -> 001181004093 | J12: =IF(ISBLANK(Merge19!S6),"",Merge19!S6) -> Giáo viên tiểu học hạng II – V.07.03.28 | K12: 5
A13: 6 | B13: 366 | C13: Nguyễn Thị Nhung | D13: NGUYEN THI NHUNG | E13: 1978 | F13: THPT | G13: THPT Đông Anh | H13: Thư Lâm | I13: =IF(ISBLANK(Merge19!T7), IF(ISBLANK(Merge19!U7), "", Merge19!U7),Merge19!T7& IF(ISBLANK(Merge19!U7), "", "-"&Merge19!U7)) -> 001178029862 | J13: =IF(ISBLANK(Merge19!S7),"",Merge19!S7) -> Giáo viên trung học cơ sở hạng II - V.07.04.31 | K13: 5
A14: 7 | B14: 367 | C14: Nguyễn Thế Huệ | D14: NGUYEN THE HUE | E14: 1977 | F14: THPT | G14: THPT Đông Anh | H14: Thư Lâm | I14: =IF(ISBLANK(Merge19!T9), IF(ISBLANK(Merge19!U9), "", Merge19!U9),Merge19!T9& IF(ISBLANK(Merge19!U9), "", "-"&Merge19!U9)) -> 001077040753 | J14: Giáo viên trung học phổ thông hạng III - V.07.05.15 | K14: 5
A15: 8 | B15: 368 | C15: Nguyễn Thị Nga | D15: NGUYEN THI NGA | E15: 1985 | F15: THPT | G15: THPT Tiến Thịnh | H15: Yên Lãng | I15: 35185004411 | J15: Giáo viên trung học phổ thông hạng II - V.07.05.14 | K15: 5
A16: 9 | B16: 369 | C16: Phùng Thu Hường | D16: PHUNG THU HUONG | E16: 1987 | F16: TH | G16: TH Tự Lập B | H16: Tiến Thắng | I16: =IF(ISBLANK(Merge19!T10), IF(ISBLANK(Merge19!U10), "", Merge19!U10),Merge19!T10& IF(ISBLANK(Merge19!U10), "", "-"&Merge19!U10)) -> 001085037860 | J16: =IF(ISBLANK(Merge19!S10),"",Merge19!S10) -> Giáo viên tiểu học hạng IV - V.07.03.09 | K16: 5
A17: 10 | B17: 370 | C17: Đoàn Phương Thảo | D17: DOAN PHUONG THAO | E17: 1983 | F17: TH | G17: TH Thanh Lâm B | H17: Quang Minh | I17: =IF(ISBLANK(Merge19!T11), IF(ISBLANK(Merge19!U11), "", Merge19!U11),Merge19!T11& IF(ISBLANK(Merge19!U11), "", "-"&Merge19!U11)) -> 024182000152 | J17: =IF(ISBLANK(Merge19!S11),"",Merge19!S11) -> Giáo viên trung học phổ thông hạng III - V.07.05.15 | K17: 5
A18: 11 | B18: 371 | C18: Nguyễn Thanh Hà | D18: NGUYEN THANH HA | E18: 1984 | F18: TH | G18: TH Chu Phan | H18: Yên Lãng | I18: =IF(ISBLANK(Merge19!T12), IF(ISBLANK(Merge19!U12), "", Merge19!U12),Merge19!T12& IF(ISBLANK(Merge19!U12), "", "-"&Merge19!U12)) -> 001176046317 | J18: =IF(ISBLANK(Merge19!S12),"",Merge19!S12) -> Giáo viên trung học phổ thông hạng III - V.07.05.15 | K18: 5
A19: 12 | B19: 372 | C19: Nguyễn Hoài Thanh | D19: NGUYEN HOAI THANH | E19: 1978 | F19: TH | G19: TH Đại Thịnh B | H19: Quang Minh | I19: =IF(ISBLANK(Merge19!T13), IF(ISBLANK(Merge19!U13), "", Merge19!U13),Merge19!T13& IF(ISBLANK(Merge19!U13), "", "-"&Merge19!U13)) -> 001187032876 | J19: =IF(ISBLANK(Merge19!S13),"",Merge19!S13) -> Giáo viên tiểu học hạng III – V.07.03.29 | K19: 5
A20: 13 | B20: 373 | C20: Nguyễn Văn Bằng | D20: NGUYEN VAN BANG | E20: 1985 | F20: TH | G20: TH Tự Lập A | H20: Tiến Thắng | I20: =IF(ISBLANK(Merge19!T14), IF(ISBLANK(Merge19!U14), "", Merge19!U14),Merge19!T14& IF(ISBLANK(Merge19!U14), "", "-"&Merge19!U14)) -> 001184017736 | J20: =IF(ISBLANK(Merge19!S14),"",Merge19!S14) -> Giáo viên trung học phổ thông hạng III - V.07.05.15 | K20: 5
A21: 14 | B21: 374 | C21: Lê Thị Loan | D21: LE THI LOAN | E21: 1981 | F21: TH | G21: TH Thạch Đà B | H21: Yên Lãng | I21: 1181004093 | J21: Giáo viên tiểu học hạng II – V.07.03.28 | K21: 5
A22: 15 | B22: 375 | C22: Nguyễn Thị Hằng | D22: NGUYEN THI HANG | E22: 1982 | F22: TH | G22: TH Mê Linh | H22: Mê Linh | I22: 987892839 | J22: Giáo viên tiểu học hạng III - V07.03.08 | K22: 5
A23: 16 | B23: 376 | C23: Lê Thị Hạnh | D23: LE THI HANH | E23: 1978 | F23: THCS | G23: THCS Tráng Việt | H23: Mê Linh | I23: 1178029862 | J23: Giáo viên trung học cơ sở hạng II - V.07.04.31 | K23: 5
A24: 17 | B24: 377 | C24: Nguyễn Thị Thắm | D24: NGUYEN THI THAM | E24: 1978 | F24: THCS | G24: THCS Tiền Phong | H24: Mê Linh | I24: 1178010346 | J24: Giáo viên trung học cơ sở hạng II - V.07.04.31 | K24: 5
A25: 18 | B25: 378 | C25: Nguyễn Thu Hường | D25: NGUYEN THU HUONG | E25: 1982 | F25: THCS | G25: THCS Văn Khê | H25: Mê Linh | I25: 26182001327 | J25: Giáo viên trung học cơ sở hạng II - V.07.04.31 | K25: 5
A26: 19 | B26: 379 | C26: Nguyễn Văn Dũng | D26: NGUYEN VAN DUNG | E26: 1979 | F26: THCS | G26: THCS Văn Khê | H26: Mê Linh | I26: 1079050226 | J26: Giáo viên trung học cơ sở hạng II - V.07.04.31 | K26: 5
A27: 20 | B27: 380 | C27: Nguyễn Thị Tuyết | D27: NGUYEN THI TUYET | E27: 1981 | F27: THCS | G27: THCS Văn Khê | H27: Mê Linh | I27: 1181043471 | J27: Giáo viên trung học cơ sở hạng II - V.07.04.31 | K27: 5
F28: SỞ GIÁO DỤC & ĐÀO TẠO HÀ NỘI | N28: ĐẠI DIỆN ĐƠN VỊ ĐÀO TẠO
A29: Số học viên đã thi và được cấp chứng chỉ:
A30: Số học viên đạt kết quả đầu ra:
A31: Số học viên không đạt kết quả đầu ra:
A32: Số học viên thuộc diện bất khả kháng
A33: Số học viên được thanh toán:

Sheet 20
A1: DANH SÁCH THI VÀ KẾT QUẢ THI IELTS ĐẦU RA
A2: Mã lớp: 20
A3: Đơn vị đào tạo: CÔNG TY CỔ PHẦN TRUNG TÂM ANH NGỮ AMA VINH
A5: TT | B5: Mã HV | C5: HỌ VÀ TÊN | D5: Ho va ten | E5: NĂM SINH | F5: BẬC DẠY | G5: ĐƠN VỊ CÔNG TÁC | H5: PHƯỜNG/XÃ | I5: Số CCCD/ Hộ chiếu | J5: Mã ngạch viên chức | K5: Điểm IELTS đầu vào | L5: Điểm IELTS đầu ra cần đạt | M5: Kết quả thi IELTS đầu ra | R5: KẾT QUẢ (Đạt/Không đạt)
M6: Nghe | N6: Đọc | O6: Viết | P6: Nói | Q6: Điểm IELTS đầu ra
A7: Column1 | B7: Column2 | C7: Column3 | D7: Column4 | E7: Column5 | F7: Column6 | G7: Column7 | H7: Column8 | I7: Column9 | J7: Column10 | K7: Column11 | L7: Column12 | M7: Column13 | N7: Column14 | O7: Column15 | P7: Column16 | Q7: Column17 | R7: Column18
A8: 1 | B8: 381 | C8: Trần Thị Bích Hiển | D8: TRAN THI BICH HIEN | E8: 1979 | F8: THCS | G8: THCS Tam Đồng | H8: Tiến Thắng | I8: =IF(ISBLANK(Merge20!T2), IF(ISBLANK(Merge20!U2), "", Merge20!U2),Merge20!T2& IF(ISBLANK(Merge20!U2), "", "-"&Merge20!U2)) -> 001079033488-C510532707 | J8: =IF(ISBLANK(Merge20!S2),"",Merge20!S2) -> Giáo viên trung học cơ sở hạng I - V.07.04.30 | K8: 5
A9: 2 | B9: 382 | C9: Trần Thị Thu Hằng | D9: TRAN THI THU HANG | E9: 1983 | F9: TH | G9: TH Văn Khê B | H9: Mê Linh | I9: =IF(ISBLANK(Merge20!T3), IF(ISBLANK(Merge20!U3), "", Merge20!U3),Merge20!T3& IF(ISBLANK(Merge20!U3), "", "-"&Merge20!U3)) -> 001176033068 | J9: =IF(ISBLANK(Merge20!S3),"",Merge20!S3) -> Giáo viên trung học cơ sở hạng II - V.07.04.31 | K9: 5
A10: 3 | B10: 383 | C10: Nguyễn Thị Kim Anh | D10: NGUYEN THI KIM ANH | E10: 1984 | F10: THCS | G10: THCS Tự Lập | H10: Tiến Thắng | I10: =IF(ISBLANK(Merge20!T4), IF(ISBLANK(Merge20!U4), "", Merge20!U4),Merge20!T4& IF(ISBLANK(Merge20!U4), "", "-"&Merge20!U4)) -> 001075010580 | J10: =IF(ISBLANK(Merge20!S4),"",Merge20!S4) -> Giáo viên trung học cơ sở hạng II - V.07.04.31 | K10: 5
A11: 4 | B11: 384 | C11: Nguyễn Minh Dung | D11: NGUYEN MINH DUNG | E11: 1979 | F11: THCS | G11: THCS Kim Hoa | H11: Quang Minh | I11: =IF(ISBLANK(Merge20!T5), IF(ISBLANK(Merge20!U5), "", Merge20!U5),Merge20!T5& IF(ISBLANK(Merge20!U5), "", "-"&Merge20!U5)) -> ‘001177017369 | J11: =IF(ISBLANK(Merge20!S5),"",Merge20!S5) -> Giáo viên trung học cơ sở hạng II - V.07.04.31 | K11: 5
A12: 5 | B12: 385 | C12: Nguyễn Văn Khiêm | D12: NGUYEN VAN KHIEM | E12: 1977 | F12: THCS | G12: THCS Chu Phan | H12: Yên Lãng | I12: =IF(ISBLANK(Merge20!T6), IF(ISBLANK(Merge20!U6), "", Merge20!U6),Merge20!T6& IF(ISBLANK(Merge20!U6), "", "-"&Merge20!U6)) -> 001175013832 | J12: Giáo viên trung học cơ sở hạng II - V.07.04.31 | K12: 4.5
A13: 6 | B13: 386 | C13: Nguyễn Thị Hoa | D13: NGUYEN THI HOA | E13: 1996 | F13: TH | G13: TH An Dương | H13: Hồng Hà | I13: =IF(ISBLANK(Merge20!T7), IF(ISBLANK(Merge20!U7), "", Merge20!U7),Merge20!T7& IF(ISBLANK(Merge20!U7), "", "-"&Merge20!U7)) -> 026179008039 | J13: =IF(ISBLANK(Merge20!S7),"",Merge20!S7) -> Giáo viên trung học cơ sở hạng II - V.07.04.31 | K13: 5
A14: 7 | B14: 387 | C14: Quách Thị Thanh Trà | D14: QUACH THI THANH TRA | E14: 1979 | F14: THPT | G14: THPT Minh Phú | H14: Kim Anh | I14: =IF(ISBLANK(Merge20!T8), IF(ISBLANK(Merge20!U8), "", Merge20!U8),Merge20!T8& IF(ISBLANK(Merge20!U8), "", "-"&Merge20!U8)) -> 001176004956 | J14: =IF(ISBLANK(Merge20!S8),"",Merge20!S8) -> Giáo viên trung học phổ thông hạng III - V.07.05.15 | K14: 4.5
A15: 8 | B15: 388 | C15: Lê Thị Dung | D15: LE THI DUNG | E15: 1977 | F15: THPT | G15: THPT Sóc Sơn | H15: Sóc Sơn | I15: =IF(ISBLANK(Merge20!T9), IF(ISBLANK(Merge20!U9), "", Merge20!U9),Merge20!T9& IF(ISBLANK(Merge20!U9), "", "-"&Merge20!U9)) -> 001077024738 | J15: =IF(ISBLANK(Merge20!S9),"",Merge20!S9) -> Giáo viên trung học cơ sở hạng II - V.07.04.31 | K15: 5
A16: 9 | B16: 389 | C16: Trần Thị Huệ | D16: TRAN THI HUE | E16: 1976 | F16: THPT | G16: THPT Trung Giã | H16: Trung Giã | I16: =IF(ISBLANK(Merge20!T10), IF(ISBLANK(Merge20!U10), "", Merge20!U10),Merge20!T10& IF(ISBLANK(Merge20!U10), "", "-"&Merge20!U10)) -> 001177014103 | J16: =IF(ISBLANK(Merge20!S10),"",Merge20!S10) -> Giáo viên trung học phổ thông hạng III - V.07.05.15 | K16: 5
A17: 10 | B17: 390 | C17: Nguyễn Ngọc Tuân | D17: NGUYEN NGOC TUAN | E17: 1975 | F17: THPT | G17: THPT Minh Phú | H17: Kim Anh | I17: =IF(ISBLANK(Merge20!T11), IF(ISBLANK(Merge20!U11), "", Merge20!U11),Merge20!T11& IF(ISBLANK(Merge20!U11), "", "-"&Merge20!U11)) -> 001178022441 | J17: =IF(ISBLANK(Merge20!S11),"",Merge20!S11) -> Giáo viên trung học cơ sở hạng II - V.07.04.31 | K17: 5
A18: 11 | B18: 391 | C18: Đàm Thị Tú Uyên | D18: DAM THI TU UYEN | E18: 1978 | F18: THCS | G18: THCS Phú Minh | H18: Nội Bài | I18: =IF(ISBLANK(Merge20!T12), IF(ISBLANK(Merge20!U12), "", Merge20!U12),Merge20!T12& IF(ISBLANK(Merge20!U12), "", "-"&Merge20!U12)) -> 001179000066 | J18: =IF(ISBLANK(Merge20!S12),"",Merge20!S12) -> Giáo viên trung học cơ sở hạng III - V.07.04.32 | K18: 5
A19: 12 | B19: 392 | C19: Hoàng Thị Oanh | D19: HOANG THI OANH | E19: 1976 | F19: THCS | G19: THCS Phú Minh | H19: Nội Bài | I19: =IF(ISBLANK(Merge20!T13), IF(ISBLANK(Merge20!U13), "", Merge20!U13),Merge20!T13& IF(ISBLANK(Merge20!U13), "", "-"&Merge20!U13)) -> 001194046711 | J19: =IF(ISBLANK(Merge20!S13),"",Merge20!S13) -> Giáo viên trung học cơ sở hạng II - V.07.04.31 | K19: 5
A20: 13 | B20: 393 | C20: Nguyễn Thị Hồng Thắm | D20: NGUYEN THI HONG THAM | E20: 1977 | F20: THCS | G20: THCS Nam Sơn | H20: Trung Giã | I20: =IF(ISBLANK(Merge20!T14), IF(ISBLANK(Merge20!U14), "", Merge20!U14),Merge20!T14& IF(ISBLANK(Merge20!U14), "", "-"&Merge20!U14)) -> ‘001178001577 | J20: =IF(ISBLANK(Merge20!S14),"",Merge20!S14) -> Giáo viên trung học cơ sở hạng II - V.07.04.31 | K20: 4.5
A21: 14 | B21: 394 | C21: Tạ Quang Nguyên | D21: TA QUANG NGUYEN | E21: 1975 | F21: THCS | G21: THCS Hồng Kỳ | H21: Trung Giã | I21: =IF(ISBLANK(Merge20!T15), IF(ISBLANK(Merge20!U15), "", Merge20!U15),Merge20!T15& IF(ISBLANK(Merge20!U15), "", "-"&Merge20!U15)) -> 026176000273 | J21: =IF(ISBLANK(Merge20!S15),"",Merge20!S15) -> Giáo viên trung học cơ sở hạng II - V.07.04.31 | K21: 5
A22: 15 | B22: 395 | C22: Trịnh Thị Thu Hường | D22: TRINH THI THU HUONG | E22: 1975 | F22: THCS | G22: THCS Trung Giã | H22: Trung Giã | I22: =IF(ISBLANK(Merge20!T16), IF(ISBLANK(Merge20!U16), "", Merge20!U16),Merge20!T16& IF(ISBLANK(Merge20!U16), "", "-"&Merge20!U16)) -> 001179047464 | J22: =IF(ISBLANK(Merge20!S16),"",Merge20!S16) -> Giáo viên trung học phổ thông hạng III - V.07.05.15 | K22: 5
A23: 16 | B23: 739 | C23: Trần Thị Trang | D23: TRAN THI TRANG | E23: 1987 | F23: THPT | G23: THPT Ngọc Tảo | H23: Phúc Thọ | I23: 1187041867 | J23: Giáo viên trung học phổ thông hạng III - V.07.05.15 | K23: 5
A24: 17 | B24: 16 | C24: Nguyễn Thu Trang | D24: NGUYEN THU TRANG | E24: 1979 | F24: THCS | G24: THCS Nguyễn Công Trứ | H24: Ba Đình | I24: 1179000066 | J24: Giáo viên trung học cơ sở hạng III - V.07.04.32 | K24: 4.5
A25: 18 | B25: 398 | C25: Nguyễn Thị Bích Ngọc | D25: NGUYEN THI BICH NGOC | E25: 1976 | F25: THCS | G25: THCS Mai Đình | H25: Sóc Sơn | I25: 1176033068 | J25: Giáo viên trung học cơ sở hạng II - V.07.04.31 | K25: 5
A26: 19 | B26: 399 | C26: Bùi Thị Mai Thanh | D26: BUI THI MAI THANH | E26: 1975 | F26: THCS | G26: THCS Nguyễn Du | H26: Sóc Sơn | I26: 1175032774 | J26: Giáo viên trung học cơ sở hạng II - V.07.04.31 | K26: 6
A27: 20 | B27: 400 | C27: Trần Thị Tâm | D27: TRAN THI TAM | E27: 1978 | F27: THCS | G27: THCS Tiên Dược | H27: Sóc Sơn | I27: 1178001577 | J27: Giáo viên trung học cơ sở hạng II - V.07.04.31 | K27: 6
F28: SỞ GIÁO DỤC & ĐÀO TẠO HÀ NỘI | N28: ĐẠI DIỆN ĐƠN VỊ ĐÀO TẠO
A29: Số học viên đã thi và được cấp chứng chỉ:
A30: Số học viên đạt kết quả đầu ra:
A31: Số học viên không đạt kết quả đầu ra:
A32: Số học viên thuộc diện bất khả kháng
A33: Số học viên được thanh toán:

Sheet 21
A1: DANH SÁCH THI VÀ KẾT QUẢ THI IELTS ĐẦU RA
A2: Mã lớp: 21
A3: Đơn vị đào tạo: CÔNG TY CỔ PHẦN TRUNG TÂM ANH NGỮ AMA VINH
A5: TT | B5: Mã HV | C5: HỌ VÀ TÊN | D5: Ha va ten | E5: NĂM SINH | F5: BẬC DẠY | G5: ĐƠN VỊ CÔNG TÁC | H5: PHƯỜNG/XÃ | I5: Số CCCD/ Hộ chiếu | J5: Mã ngạch viên chức | K5: Điểm IELTS đầu vào | L5: Điểm IELTS đầu ra cần đạt | M5: Kết quả thi IELTS đầu ra | R5: KẾT QUẢ (Đạt/Không đạt)
M6: Nghe | N6: Đọc | O6: Viết | P6: Nói | Q6: Điểm IELTS đầu ra
A7: Column1 | B7: Column2 | C7: Column3 | D7: Column4 | E7: Column5 | F7: Column6 | G7: Column7 | H7: Column8 | I7: Column9 | J7: Column10 | K7: Column11 | L7: Column12 | M7: Column13 | N7: Column14 | O7: Column15 | P7: Column16 | Q7: Column17 | R7: Column18
A8: 1 | B8: 401 | C8: Trần Mai Hương | D8: TRAN MAI HUONG | E8: 1975 | F8: THCS | G8: THCS Phù Linh | H8: Sóc Sơn | I8: =IF(ISBLANK(Merge21!T2), IF(ISBLANK(Merge21!U2), "", Merge21!U2),Merge21!T2& IF(ISBLANK(Merge21!U2), "", "-"&Merge21!U2)) -> 001174036478 | J8: =IF(ISBLANK(Merge21!S2),"",Merge21!S2) -> Giáo viên trung học cơ sở hạng II - V.07.04.31 | K8: 5
A9: 2 | B9: 402 | C9: Phạm Thị Mai Phúc | D9: PHAM THI MAI PHUC | E9: 1976 | F9: THCS | G9: THCS Phù Linh | H9: Phù Linh | I9: =IF(ISBLANK(Merge21!T3), IF(ISBLANK(Merge21!U3), "", Merge21!U3),Merge21!T3& IF(ISBLANK(Merge21!U3), "", "-"&Merge21!U3)) -> 001077036817 | J9: =IF(ISBLANK(Merge21!S3),"",Merge21!S3) -> Giáo viên trung học cơ sở hạng II - V.07.04.31 | K9: 5
A10: 3 | B10: 403 | C10: Nguyễn Thị Hoà | D10: NGUYEN THI HOA | E10: 1994 | F10: THCS | G10: THCS Vân Hà | H10: Thư Lâm | I10: =IF(ISBLANK(Merge21!T4), IF(ISBLANK(Merge21!U4), "", Merge21!U4),Merge21!T4& IF(ISBLANK(Merge21!U4), "", "-"&Merge21!U4)) -> 001175023937 | J10: =IF(ISBLANK(Merge21!S4),"",Merge21!S4) -> Giáo viên trung học cơ sở hạng II - V.07.04.31 | K10: 5.5
A11: 4 | B11: 404 | C11: Nguyễn Thị Huệ | D11: NGUYEN THI HUE | E11: 1979 | F11: THCS | G11: THCS Dục Tú | H11: Đông Anh | I11: =IF(ISBLANK(Merge21!T5), IF(ISBLANK(Merge21!U5), "", Merge21!U5),Merge21!T5& IF(ISBLANK(Merge21!U5), "", "-"&Merge21!U5)) -> 001194006005 | J11: =IF(ISBLANK(Merge21!S5),"",Merge21!S5) -> Giáo viên trung học cơ sở hạng III - V.07.04.32 | K11: 5.5
A12: 5 | B12: 405 | C12: Lê Anh Tuấn | D12: LE ANH TUAN | E12: 1979 | F12: THCS | G12: THCS Đông Thái | H12: Tây Hồ | I12: =IF(ISBLANK(Merge21!T6), IF(ISBLANK(Merge21!U6), "", Merge21!U6),Merge21!T6& IF(ISBLANK(Merge21!U6), "", "-"&Merge21!U6)) -> 008179000026 | J12: =IF(ISBLANK(Merge21!S6),"",Merge21!S6) -> Giáo viên trung học cơ sở hạng II - V.07.04.31 | K12: 5.5
A13: 6 | B13: 406 | C13: Đào Thị Thúy Hà | D13: DAO THI THUY HA | E13: 1979 | F13: THCS | G13: THCS Vĩnh Ngọc | H13: Vĩnh Thanh | I13: =IF(ISBLANK(Merge21!T7), IF(ISBLANK(Merge21!U7), "", Merge21!U7),Merge21!T7& IF(ISBLANK(Merge21!U7), "", "-"&Merge21!U7)) -> 001079024981 | J13: =IF(ISBLANK(Merge21!S7),"",Merge21!S7) -> Giáo viên trung học cơ sở hạng II - V.07.04.31 | K13: 5
A14: 7 | B14: 407 | C14: Nguyễn Thị Lan Anh | D14: NGUYEN THI LAN ANH | E14: 1978 | F14: THCS | G14: THCS Đông Hội | H14: Đông Anh | I14: =IF(ISBLANK(Merge21!T8), IF(ISBLANK(Merge21!U8), "", Merge21!U8),Merge21!T8& IF(ISBLANK(Merge21!U8), "", "-"&Merge21!U8)) -> 001184039143 | J14: =IF(ISBLANK(Merge21!S8),"",Merge21!S8) -> Giáo viên tiểu học hạng III – V.07.03.29 | K14: 5.5
A15: 8 | B15: 408 | C15: Nguyễn Ngọc Quân | D15: NGUYEN NGOC QUAN | E15: 1974 | F15: THCS | G15: THCS Thụy Lâm | H15: Phúc Thịnh | I15: =IF(ISBLANK(Merge21!T9), IF(ISBLANK(Merge21!U9), "", Merge21!U9),Merge21!T9& IF(ISBLANK(Merge21!U9), "", "-"&Merge21!U9)) -> 001177046284 | J15: =IF(ISBLANK(Merge21!S9),"",Merge21!S9) -> Giáo viên trung học phổ thông hạng III - V.07.05.15 | K15: 4.5
A16: 9 | B16: 409 | C16: Ngô Văn Việt | D16: NGO VAN VIET | E16: 1977 | F16: THCS | G16: THCS An Dương Vương | H16: Đông Anh | I16: =IF(ISBLANK(Merge21!T10), IF(ISBLANK(Merge21!U10), "", Merge21!U10),Merge21!T10& IF(ISBLANK(Merge21!U10), "", "-"&Merge21!U10)) -> 001180044201 | J16: =IF(ISBLANK(Merge21!S10),"",Merge21!S10) -> Giáo viên tiểu học hạng III – V.07.03.29 | K16: 5.5
A17: 10 | B17: 410 | C17: Lê Thị Hương | D17: LE THI HUONG | E17: 1976 | F17: THCS | G17: THCS Kim Chung | H17: Thiên Lộc | I17: =IF(ISBLANK(Merge21!T11), IF(ISBLANK(Merge21!U11), "", Merge21!U11),Merge21!T11& IF(ISBLANK(Merge21!U11), "", "-"&Merge21!U11)) -> 001178021999 | J17: =IF(ISBLANK(Merge21!S11),"",Merge21!S11) -> Giáo viên trung học cơ sở hạng II - V.07.04.31 | K17: 5.5
A18: 11 | B18: 411 | C18: Phạm Thị Chính | D18: PHAM THI CHINH | E18: 1975 | F18: THCS | G18: THCS Cổ Loa | H18: Đông Anh | I18: =IF(ISBLANK(Merge21!T12), IF(ISBLANK(Merge21!U12), "", Merge21!U12),Merge21!T12& IF(ISBLANK(Merge21!U12), "", "-"&Merge21!U12)) -> 001194046711 | J18: =IF(ISBLANK(Merge21!S12),"",Merge21!S12) -> Giáo viên trung học cơ sở hạng II - V.07.04.31 | K18: 5.5
A19: 12 | B19: 412 | C19: Lê Thị Mai Lan | D19: LE THI MAI LAN | E19: 1974 | F19: THCS | G19: THCS Tiên Dương | H19: Đông Anh | I19: =IF(ISBLANK(Merge21!T13), IF(ISBLANK(Merge21!U13), "", Merge21!U13),Merge21!T13& IF(ISBLANK(Merge21!U13), "", "-"&Merge21!U13)) -> 001196039783 | J19: =IF(ISBLANK(Merge21!S13),"",Merge21!S13) -> Giáo viên tiểu học hạng III – V.07.03.29 | K19: 4.5
A20: 13 | B20: 413 | C20: Phạm Thị Cúc | D20: PHAM THI CUC | E20: 1989 | F20: THPT | G20: THPT Cổ Loa | H20: Đông Anh | I20: =IF(ISBLANK(Merge21!T14), IF(ISBLANK(Merge21!U14), "", Merge21!U14),Merge21!T14& IF(ISBLANK(Merge21!U14), "", "-"&Merge21!U14)) -> 001189011826 | J20: =IF(ISBLANK(Merge21!S14),"",Merge21!S14) -> Giáo viên trung học phổ thông hạng III - V.07.05.15 | K20: 5.5
A21: 14 | B21: 414 | C21: Chử Thị Thu Trang | D21: CHU THI THU TRANG | E21: 1978 | F21: THPT | G21: THPT Cổ Loa | H21: Đông Anh | I21: 1178002480 | J21: Giáo viên trung học phổ thông hạng III - V.07.05.15 | K21: 5.5
A22: 15 | B22: 415 | C22: Lê Thị Hải | D22: LE THI HAI | E22: 1977 | F22: THPT | G22: THPT Liên Hà | H22: Thư Lâm | I22: 1184039143 | J22: Giáo viên tiểu học hạng III – V.07.03.29 | K22: 5.5
A23: 16 | B23: 416 | C23: Nguyễn Thị Thu Hương | D23: NGUYEN THI THU HUONG | E23: 1976 | F23: THPT | G23: THPT Liên Hà | H23: Thư Lâm | I23: 27176011754 | J23: Giáo viên trung học phổ thông hạng III - V.07.05.15 | K23: 5.5
A24: 17 | B24: 417 | C24: Phạm Quỳnh Liên | D24: PHAM QUYNH LIEN | E24: 1996 | F24: TH | G24: TH Võng La | H24: Thiên Lộc | I24: 1196039783 | J24: Giáo viên tiểu học hạng III – V.07.03.29 | K24: 5.5
A25: 18 | B25: 418 | C25: Dương Thị Thu Phương | D25: DUONG THI THU PHUONG | E25: 1993 | F25: TH | G25: TH Thị Trấn | H25: Thư Lâm | I25: 1193046294 | J25: Giáo viên tiểu học hạng III – V.07.03.29 | K25: 5
A26: 19 | B26: 419 | C26: Nguyễn Thị Hồng Huệ | D26: NGUYEN THI HONG HUE | E26: 1980 | F26: TH | G26: TH Kim Nỗ | H26: Thiên Lộc | I26: 1180044201 | J26: Giáo viên tiểu học hạng III – V.07.03.29 | K26: 5.5
A27: 20 | B27: 420 | C27: Nguyễn Thị Minh Hiển | D27: NGUYEN THI MINH HIEN | E27: 1979 | F27: TH | G27: TH Võng La | H27: Thiên Lộc | I27: 1179003519 | J27: Giáo viên tiểu học hạng II – V.07.03.28 | K27: 5.5
F28: SỞ GIÁO DỤC & ĐÀO TẠO HÀ NỘI | N28: ĐẠI DIỆN ĐƠN VỊ ĐÀO TẠO
A29: Số học viên đã thi và được cấp chứng chỉ:
A30: Số học viên đạt kết quả đầu ra:
A31: Số học viên không đạt kết quả đầu ra:
A32: Số học viên thuộc diện bất khả kháng
A33: Số học viên được thanh toán:

Sheet 22
A1: DANH SÁCH THI VÀ KẾT QUẢ THI IELTS ĐẦU RA
A2: Mã lớp: 22
A3: Đơn vị đào tạo: CÔNG TY CỔ PHẦN TRUNG TÂM ANH NGỮ AMA VINH
A5: TT | B5: Mã HV | C5: HỌ VÀ TÊN | D5: Ho va ten | E5: NĂM SINH | F5: BẬC DẠY | G5: ĐƠN VỊ CÔNG TÁC | H5: PHƯỜNG/XÃ | I5: Số CCCD/ Hộ chiếu | J5: Mã ngạch viên chức | K5: Điểm IELTS đầu vào | L5: Điểm IELTS đầu ra cần đạt | M5: Kết quả thi IELTS đầu ra | R5: KẾT QUẢ (Đạt/Không đạt)
M6: Nghe | N6: Đọc | O6: Viết | P6: Nói | Q6: Điểm IELTS đầu ra
A7: Column1 | B7: Column2 | C7: Column3 | D7: Column4 | E7: Column5 | F7: Column6 | G7: Column7 | H7: Column8 | I7: Column9 | J7: Column10 | K7: Column11 | L7: Column12 | M7: Column13 | N7: Column14 | O7: Column15 | P7: Column16 | Q7: Column17 | R7: Column18
A8: 1 | B8: 421 | C8: Vũ Thị Kim Thanh | D8: VU THI KIM THANH | E8: 1978 | F8: TH | G8: TH Tô Thị Hiển | H8: Phúc Thịnh | I8: =IF(ISBLANK(Merge22!T2), IF(ISBLANK(Merge22!U2), "", Merge22!U2),Merge22!T2& IF(ISBLANK(Merge22!U2), "", "-"&Merge22!U2)) -> 001194006005 | J8: =IF(ISBLANK(Merge22!S2),"",Merge22!S2) -> Giáo viên trung học cơ sở hạng III - V.07.04.32 | K8: 5
A9: 2 | B9: 422 | C9: Nguyễn Thị Hồng Kiểm | D9: NGUYEN THI HONG KIEM | E9: 1977 | F9: TH | G9: TH Cổ Loa | H9: Đông Anh | I9: =IF(ISBLANK(Merge22!T3), IF(ISBLANK(Merge22!U3), "", Merge22!U3),Merge22!T3& IF(ISBLANK(Merge22!U3), "", "-"&Merge22!U3)) -> 001176053581 | J9: =IF(ISBLANK(Merge22!S3),"",Merge22!S3) -> Giáo viên trung học phổ thông hạng III - V.07.05.15 | K9: 5.5
A10: 3 | B10: 423 | C10: Nguyễn Thị Châm | D10: NGUYEN THI CHAM | E10: 1977 | F10: TH | G10: TH Thăng Long | H10: Thiên Lộc | I10: =IF(ISBLANK(Merge22!T4), IF(ISBLANK(Merge22!U4), "", Merge22!U4),Merge22!T4& IF(ISBLANK(Merge22!U4), "", "-"&Merge22!U4)) -> 001180020741 | J10: =IF(ISBLANK(Merge22!S4),"",Merge22!S4) -> Giáo viên tiểu học hạng II – V.07.03.28 | K10: 5.5
A11: 4 | B11: 424 | C11: Đàm Thị Thu Điệp | D11: DAM THI THU DIEP | E11: 1977 | F11: TH | G11: TH Vĩnh Ngọc | H11: Vĩnh Thanh | I11: =IF(ISBLANK(Merge22!T5), IF(ISBLANK(Merge22!U5), "", Merge22!U5),Merge22!T5& IF(ISBLANK(Merge22!U5), "", "-"&Merge22!U5)) -> 001178013783 | J11: =IF(ISBLANK(Merge22!S5),"",Merge22!S5) -> Giáo viên tiểu học hạng III – V.07.03.29 | K11: 5.5
A12: 5 | B12: 425 | C12: Cao Thị Bằng | D12: CAO THI BANG | E12: 1976 | F12: TH | G12: TH Dục Tú | H12: Đông Anh | I12: =IF(ISBLANK(Merge22!T6), IF(ISBLANK(Merge22!U6), "", Merge22!U6),Merge22!T6& IF(ISBLANK(Merge22!U6), "", "-"&Merge22!U6)) -> 001196039158 | J12: =IF(ISBLANK(Merge22!S6),"",Merge22!S6) -> Giáo viên trung học cơ sở hạng III - V.07.04.32 | K12: 5.5
A13: 6 | B13: 426 | C13: Nguyễn Thị Thu Uyên | D13: NGUYEN THI THU UYEN | E13: 1996 | F13: THCS | G13: THCS Cổ Loa | H13: Đông Anh | I13: =IF(ISBLANK(Merge22!T7), IF(ISBLANK(Merge22!U7), "", Merge22!U7),Merge22!T7& IF(ISBLANK(Merge22!U7), "", "-"&Merge22!U7)) -> 001177019255 | J13: =IF(ISBLANK(Merge22!S7),"",Merge22!S7) -> Giáo viên tiểu học hạng III - V07.03.08 | K13: 5.5
A14: 7 | B14: 427 | C14: Lương Thị Hồng Nhung | D14: LUONG THI HONG NHUNG | E14: 1996 | F14: THCS | G14: THCS Mai Lâm | H14: Đông Anh | I14: =IF(ISBLANK(Merge22!T8), IF(ISBLANK(Merge22!U8), "", Merge22!U8),Merge22!T8& IF(ISBLANK(Merge22!U8), "", "-"&Merge22!U8)) -> 001177030526 | J14: =IF(ISBLANK(Merge22!S8),"",Merge22!S8) -> Giáo viên tiểu học hạng II – V.07.03.28 | K14: 5.5
A15: 8 | B15: 428 | C15: Nguyễn Thị Thu Hương | D15: NGUYEN THI THU HUONG | E15: 1994 | F15: THCS | G15: THCS Dục Tú | H15: Đông Anh | I15: =IF(ISBLANK(Merge22!T9), IF(ISBLANK(Merge22!U9), "", Merge22!U9),Merge22!T9& IF(ISBLANK(Merge22!U9), "", "-"&Merge22!U9)) -> 001191025902 | J15: =IF(ISBLANK(Merge22!S9),"",Merge22!S9) -> Giáo viên tiểu học hạng III – V.07.03.29 | K15: 5.5
A16: 9 | B16: 429 | C16: Nguyễn Thị Phương | D16: NGUYEN THI PHUONG | E16: 1976 | F16: THPT | G16: THPT Vân Nội | H16: Phúc Thịnh | I16: =IF(ISBLANK(Merge22!T10), IF(ISBLANK(Merge22!U10), "", Merge22!U10),Merge22!T10& IF(ISBLANK(Merge22!U10), "", "-"&Merge22!U10)) -> 001182042023 | J16: =IF(ISBLANK(Merge22!S10),"",Merge22!S10) -> Giáo viên tiểu học hạng II – V.07.03.28 | K16: 5.5
A17: 10 | B17: 430 | C17: Nguyễn Thị Mai Hương | D17: NGUYEN THI MAI HUONG | E17: 1978 | F17: THPT | G17: THPT Vân Nội | H17: Phúc Thịnh | I17: 1184057507 | J17: Giáo viên trung học cơ sở hạng II - V.07.04.31 | K17: 5.5
A18: 11 | B18: 431 | C18: Phan Thị Nhàn | D18: PHAN THI NHAN | E18: 1984 | F18: THPT | G18: THPT Bắc Thăng Long | H18: Thiên Lộc | I18: 1184006475 | J18: Giáo viên trung học phổ thông hạng III - V.07.05.15 | K18: 5.5
A19: 12 | B19: 432 | C19: Nguyễn Thị Hà | D19: NGUYEN THI HA | E19: 1982 | F19: TH | G19: TH Liên Mạc B | H19: Yên Lãng | I19: 1182042023 | J19: Giáo viên tiểu học hạng II – V.07.03.28 | K19: 5.5
A20: 13 | B20: 433 | C20: Ngô Thị Hồng Gấm | D20: NGO THI HONG GAM | E20: 1985 | F20: TH | G20: TH Văn Khê A | H20: Mê Linh | I20: 1185019297 | J20: Giáo viên tiểu học hạng II – V.07.03.28 | K20: 5.5
A21: 14 | B21: 603 | C21: Nguyễn Thanh Nhàn | D21: NGUYEN THANH NHAN | E21: 1977 | F21: TH | G21: TH Hoàng Hoa Thám | H21: Ngọc Hà | I21: 1177010105 | J21: Giáo viên tiểu học hạng II – V.07.03.28 | K21: 5.5
A22: 15 | B22: 481 | C22: Hoàng Văn Hùng | D22: HOANG VAN HUNG | E22: 1983 | F22: THPT | G22: THPT Ngọc Tảo | H22: Hát Môn | I22: 1083006421 | J22: Giáo viên trung học phổ thông hạng III - V.07.05.15 | K22: 5.5
A23: 16 | B23: 436 | C23: Vũ Thị Minh Thu | D23: VU THI MINH THU | E23: 1982 | F23: TH | G23: TH Đại Thịnh A | H23: Quang Minh | I23: 35182000293 | J23: Giáo viên tiểu học hạng II – V.07.03.28 | K23: 5.5
A24: 17 | B24: 437 | C24: Nguyễn Thị Minh Thảo | D24: NGUYEN THI MINH THAO | E24: 1987 | F24: TH | G24: TH Chi Đông | H24: Quang Minh | I24: 1187022144 | J24: Giáo viên tiểu học hạng III – V.07.03.29 | K24: 5.5
A25: 18 | B25: 438 | C25: Nguyễn Đức Chiến | D25: NGUYEN DUC CHIEN | E25: 1980 | F25: THCS | G25: THCS Văn Khê | H25: Hà Đông | I25: =IF(ISBLANK(Merge22!T19), IF(ISBLANK(Merge22!U19), "", Merge22!U19),Merge22!T19& IF(ISBLANK(Merge22!U19), "", "-"&Merge22!U19)) | J25: =IF(ISBLANK(Merge22!S19),"",Merge22!S19) | K25: 5.5
A26: 19 | B26: 439 | C26: Nguyễn Minh Mẫn | D26: NGUYEN MINH MAN | E26: 1975 | F26: THCS | G26: THCS Tiến Thắng | H26: Tiến Thắng | I26: =IF(ISBLANK(Merge22!T20), IF(ISBLANK(Merge22!U20), "", Merge22!U20),Merge22!T20& IF(ISBLANK(Merge22!U20), "", "-"&Merge22!U20)) | J26: =IF(ISBLANK(Merge22!S20),"",Merge22!S20) | K26: 5.5
A27: 20 | B27: 440 | C27: Nguyễn Thị Thịnh | D27: NGUYEN THI THINH | E27: 1980 | F27: TH | G27: TH Thạch Đà A | H27: Yên Lãng | I27: 1180020741 | J27: Giáo viên tiểu học hạng II – V.07.03.28 | K27: 5
F28: SỞ GIÁO DỤC & ĐÀO TẠO HÀ NỘI | N28: ĐẠI DIỆN ĐƠN VỊ ĐÀO TẠO
A29: Số học viên đã thi và được cấp chứng chỉ:
A30: Số học viên đạt kết quả đầu ra:
A31: Số học viên không đạt kết quả đầu ra:
A32: Số học viên thuộc diện bất khả kháng
A33: Số học viên được thanh toán:

Sheet 23
A1: DANH SÁCH THI VÀ KẾT QUẢ THI IELTS ĐẦU RA
A2: Mã lớp: 23
A3: Đơn vị đào tạo: CÔNG TY CỔ PHẦN TRUNG TÂM ANH NGỮ AMA VINH
A5: TT | B5: Mã HV | C5: HỌ VÀ TÊN | D5: Ha va ten | E5: NĂM SINH | F5: BẬC DẠY | G5: ĐƠN VỊ CÔNG TÁC | H5: PHƯỜNG/XÃ | I5: Số CCCD/ Hộ chiếu | J5: Mã ngạch viên chức | K5: Điểm IELTS đầu vào | L5: Điểm IELTS đầu ra cần đạt | M5: Kết quả thi IELTS đầu ra | R5: KẾT QUẢ (Đạt/Không đạt)
M6: Nghe | N6: Đọc | O6: Viết | P6: Nói | Q6: Điểm IELTS đầu ra
A7: Column1 | B7: Column2 | C7: Column3 | D7: Column4 | E7: Column5 | F7: Column6 | G7: Column7 | H7: Column8 | I7: Column9 | J7: Column10 | K7: Column11 | L7: Column12 | M7: Column13 | N7: Column14 | O7: Column15 | P7: Column16 | Q7: Column17 | R7: Column18
A8: 1 | B8: 441 | C8: Nguyễn Thị Hà | D8: NGUYEN THI HA | E8: 1991 | F8: TH | G8: TH Vân Hà | H8: Thư Lâm | I8: =IF(ISBLANK(Merge23!T2), IF(ISBLANK(Merge23!U2), "", Merge23!U2),Merge23!T2& IF(ISBLANK(Merge23!U2), "", "-"&Merge23!U2)) -> 002178000027 | J8: =IF(ISBLANK(Merge23!S2),"",Merge23!S2) -> Giáo viên trung học phổ thông hạng III - V.07.05.15 | K8: 5
A9: 2 | B9: 442 | C9: Nguyễn Thị Ánh | D9: NGUYEN THI ANH | E9: 1981 | F9: THCS | G9: THCS Phạm Hồng Thái | H9: Yên Lãng | I9: =IF(ISBLANK(Merge23!T3), IF(ISBLANK(Merge23!U3), "", Merge23!U3),Merge23!T3& IF(ISBLANK(Merge23!U3), "", "-"&Merge23!U3)) -> 001176049161 | J9: =IF(ISBLANK(Merge23!S3),"",Merge23!S3) -> Giáo viên trung học phổ thông hạng III - V.07.05.15 | K9: 5.5
A10: 3 | B10: 443 | C10: Lê Thị kim Oanh | D10: LE THI KIM OANH | E10: 1984 | F10: THCS | G10: THCS Liên Mạc | H10: Yên Lãng | I10: =IF(ISBLANK(Merge23!T4), IF(ISBLANK(Merge23!U4), "", Merge23!U4),Merge23!T4& IF(ISBLANK(Merge23!U4), "", "-"&Merge23!U4)) -> 027176002787 | J10: =IF(ISBLANK(Merge23!S4),"",Merge23!S4) -> Giáo viên trung học phổ thông hạng III - V.07.05.15 | K10: 5.5
A11: 4 | B11: 444 | C11: Nguyễn Công Tuấn | D11: NGUYEN CONG TUAN | E11: 1976 | F11: THCS | G11: THCS Tự Lập | H11: Tiến Thắng | I11: =IF(ISBLANK(Merge23!T5), IF(ISBLANK(Merge23!U5), "", Merge23!U5),Merge23!T5& IF(ISBLANK(Merge23!U5), "", "-"&Merge23!U5)) -> 001179028050 | J11: =IF(ISBLANK(Merge23!S5),"",Merge23!S5) -> Giáo viên trung học phổ thông hạng III - V.07.05.15 | K11: 5.5
A12: 5 | B12: 445 | C12: Lê Thị Hải | D12: LE THI HAI | E12: 1984 | F12: TH | G12: TH Hoàng Kim | H12: Yên Lãng | I12: =IF(ISBLANK(Merge23!T6), IF(ISBLANK(Merge23!U6), "", Merge23!U6),Merge23!T6& IF(ISBLANK(Merge23!U6), "", "-"&Merge23!U6)) -> 001076003003 | J12: =IF(ISBLANK(Merge23!S6),"",Merge23!S6) -> Giáo viên trung học cơ sở hạng II - V.07.04.31 | K12: 5.5
A13: 6 | B13: 446 | C13: Nguyễn Thị Hồng Phúc | D13: NGUYEN THI HONG PHUC | E13: 2000 | F13: THCS | G13: Liên Mạc | H13: Thượng Cát | I13: =IF(ISBLANK(Merge23!T7), IF(ISBLANK(Merge23!U7), "", Merge23!U7),Merge23!T7& IF(ISBLANK(Merge23!U7), "", "-"&Merge23!U7)) -> 001078028836 | J13: =IF(ISBLANK(Merge23!S7),"",Merge23!S7) -> Giáo viên trung học cơ sở hạng II - V.07.04.31 | K13: 5.5
A14: 7 | B14: 447 | C14: Đỗ Thị Thanh Thủy | D14: DO THI THANH THUY | E14: 1983 | F14: THCS | G14: THCS Trưng Vương | H14: Quang Minh | I14: =IF(ISBLANK(Merge23!T8), IF(ISBLANK(Merge23!U8), "", Merge23!U8),Merge23!T8& IF(ISBLANK(Merge23!U8), "", "-"&Merge23!U8)) -> 001184035063 | J14: =IF(ISBLANK(Merge23!S8),"",Merge23!S8) -> Giáo viên trung học cơ sở hạng II - V.07.04.31 | K14: 5.5
A15: 8 | B15: 448 | C15: Lê Xuân Hải | D15: LE XUAN HAI | E15: 1978 | F15: THCS | G15: THCS Chu Phan | H15: Mê Linh | I15: =IF(ISBLANK(Merge23!T9), IF(ISBLANK(Merge23!U9), "", Merge23!U9),Merge23!T9& IF(ISBLANK(Merge23!U9), "", "-"&Merge23!U9)) -> 026181006803 | J15: =IF(ISBLANK(Merge23!S9),"",Merge23!S9) -> Giáo viên trung học cơ sở hạng II - V.07.04.31 | K15: 5.5
A16: 9 | B16: 449 | C16: Nguyễn Thị Lệ | D16: NGUYEN THI LE | E16: 1995 | F16: THPT | G16: THPT Sóc Sơn | H16: Sóc Sơn | I16: =IF(ISBLANK(Merge23!T10), IF(ISBLANK(Merge23!U10), "", Merge23!U10),Merge23!T10& IF(ISBLANK(Merge23!U10), "", "-"&Merge23!U10)) -> 001184039143 | J16: =IF(ISBLANK(Merge23!S10),"",Merge23!S10) -> Giáo viên tiểu học hạng III – V.07.03.29 | K16: 5.5
A17: 10 | B17: 450 | C17: Phạm Thị Liên | D17: PHAM THI LIEN | E17: 1985 | F17: THPT | G17: THPT Minh Phú | H17: Kim Anh | I17: =IF(ISBLANK(Merge23!T11), IF(ISBLANK(Merge23!U11), "", Merge23!U11),Merge23!T11& IF(ISBLANK(Merge23!U11), "", "-"&Merge23!U11)) -> 001177046284 | J17: =IF(ISBLANK(Merge23!S11),"",Merge23!S11) -> Giáo viên trung học phổ thông hạng III - V.07.05.15 | K17: 5.5
A18: 11 | B18: 451 | C18: Vũ Thị Hồng Nhung | D18: VU THI HONG NHUNG | E18: 1983 | F18: THPT | G18: THPT Minh Phú | H18: Kim Anh | I18: =IF(ISBLANK(Merge23!T12), IF(ISBLANK(Merge23!U12), "", Merge23!U12),Merge23!T12& IF(ISBLANK(Merge23!U12), "", "-"&Merge23!U12)) -> 001183053186 | J18: =IF(ISBLANK(Merge23!S12),"",Merge23!S12) -> Giáo viên tiểu học hạng III – V.07.03.29 | K18: 5.5
A19: 12 | B19: 452 | C19: Trần Thanh Tùng | D19: TRAN THANH TUNG | E19: 1982 | F19: THPT | G19: THPT Trung Giã | H19: Trung Giã | I19: =IF(ISBLANK(Merge23!T13), IF(ISBLANK(Merge23!U13), "", Merge23!U13),Merge23!T13& IF(ISBLANK(Merge23!U13), "", "-"&Merge23!U13)) -> 001191025902 | J19: =IF(ISBLANK(Merge23!S13),"",Merge23!S13) -> Giáo viên tiểu học hạng III – V.07.03.29 | K19: 5.5
... A23: 16 | B23: 456 | C23: Dương Thị Dung | D23: DUONG THI DUNG | E23: 1976 | F23: THPT | G23: THPT Trung Giã | H23: Trung Giã | I23: =IF(ISBLANK(Merge23!T17), IF(ISBLANK(Merge23!U17), "", Merge23!U17),Merge23!T17& IF(ISBLANK(Merge23!U17), "", "-"&Merge23!U17)) -> 001195004906 | J23: =IF(ISBLANK(Merge23!S17),"",Merge23!S17) -> Giáo viên trung học cơ sở hạng III - V.07.04.32 | K23: 5.5
A24: 17 | B24: 457 | C24: Khổng Việt Hồng | D24: KHONG VIET HONG | E24: 1975 | F24: THPT | G24: THPT Đa Phúc | H24: Sóc Sơn | I24: 1175028245 | J24: Giáo viên trung học phổ thông hạng I - V.07.05.13 | K24: 5.5
A25: 18 | B25: 458 | C25: Vũ Thị Hảo | D25: VU THI HAO | E25: 1995 | F25: THCS | G25: THCS Thanh Xuân | H25: Nội Bài | I25: 1195004906 | J25: Giáo viên trung học cơ sở hạng III - V.07.04.32 | K25: 5.5
A26: 19 | B26: 459 | C26: Nguyễn Thị Huệ | D26: NGUYEN THI HUE | E26: 1975 | F26: THCS | G26: THCS Quang Tiến | H26: Nội Bài | I26: =IF(ISBLANK(Merge23!T20), IF(ISBLANK(Merge23!U20), "", Merge23!U20),Merge23!T20& IF(ISBLANK(Merge23!U20), "", "-"&Merge23!U20)) | J26: =IF(ISBLANK(Merge23!S20),"",Merge23!S20) | K26: 5.5
A27: 20 | B27: 460 | C27: Nguyễn Thị Hồng Yến | D27: NGUYEN THI HONG YEN | E27: 1983 | F27: TH | G27: TH Phú Minh | H27: Nội Bài | I27: 1183053186 | J27: Giáo viên tiểu học hạng III – V.07.03.29 | K27: 5
F28: SỞ GIÁO DỤC & ĐÀO TẠO HÀ NỘI | N28: ĐẠI DIỆN ĐƠN VỊ ĐÀO TẠO
A29: Số học viên đã thi và được cấp chứng chỉ:
A30: Số học viên đạt kết quả đầu ra:
A31: Số học viên không đạt kết quả đầu ra:
A32: Số học viên thuộc diện bất khả kháng
A33: Số học viên được thanh toán:

Sheet 24
A1: DANH SÁCH THI VÀ KẾT QUẢ THI IELTS ĐẦU RA
A2: Mã lớp: 24
A3: Đơn vị đào tạo: CÔNG TY CỔ PHẦN TRUNG TÂM ANH NGỮ AMA VINH
A5: TT | B5: Mã HV | C5: HỌ VÀ TÊN | D5: Ha va ten | E5: NĂM SINH | F5: BẬC DẠY | G5: ĐƠN VỊ CÔNG TÁC | H5: PHƯỜNG/XÃ | I5: Số CCCD/ Hộ chiếu | J5: Mã ngạch viên chức | K5: Điểm IELTS đầu vào | L5: Điểm IELTS đầu ra cần đạt | M5: Kết quả thi IELTS đầu ra | R5: KẾT QUẢ (Đạt/Không đạt)
M6: Nghe | N6: Đọc | O6: Viết | P6: Nói | Q6: Điểm IELTS đầu ra
A7: Column1 | B7: Column2 | C7: Column3 | D7: Column4 | E7: Column5 | F7: Column6 | G7: Column7 | H7: Column8 | I7: Column9 | J7: Column10 | K7: Column11 | L7: Column12 | M7: Column13 | N7: Column14 | O7: Column15 | P7: Column16 | Q7: Column17 | R7: Column18
A8: 1 | B8: 482 | C8: Lê Thị Bích Hường | D8: LE THI BICH HUONG | E8: 1984 | F8: THPT | G8: THPT Tiến Thịnh | H8: Yên Lãng | I8: =IF(ISBLANK(Merge24!T2), IF(ISBLANK(Merge24!U2), "", Merge24!U2),Merge24!T2& IF(ISBLANK(Merge24!U2), "", "-"&Merge24!U2)) -> 001184058569 | J8: =IF(ISBLANK(Merge24!S2),"",Merge24!S2) -> Giáo viên trung học phổ thông hạng II - V.07.05.14 | K8: 5.5
A9: 2 | B9: 462 | C9: Đặng Thị Hà | D9: DANG THI HA | E9: 1977 | F9: THCS | G9: THCS Minh Trí | H9: Kim Anh | I9: =IF(ISBLANK(Merge24!T3), IF(ISBLANK(Merge24!U3), "", Merge24!U3),Merge24!T3& IF(ISBLANK(Merge24!U3), "", "-"&Merge24!U3)) -> 001194006005 | J9: =IF(ISBLANK(Merge24!S3),"",Merge24!S3) -> Giáo viên trung học cơ sở hạng III - V.07.04.32 | K9: 5.5
A10: 3 | B10: 463 | C10: Trần Thị Minh Trang | D10: TRAN THI MINH TRANG | E10: 1989 | F10: TH | G10: TH Hương Đình | H10: Sóc Sơn | I10: =IF(ISBLANK(Merge24!T4), IF(ISBLANK(Merge24!U4), "", Merge24!U4),Merge24!T4& IF(ISBLANK(Merge24!U4), "", "-"&Merge24!U4)) -> 001178003953 | J10: =IF(ISBLANK(Merge24!S4),"",Merge24!S4) -> Giáo viên trung học phổ thông hạng III - V.07.05.15 | K10: 5.5
A11: 4 | B11: 464 | C11: Đoàn Thị Lợi | D11: DOAN THI LOI | E11: 1979 | F11: THCS | G11: THCS Đông Xuân | H11: Sóc Sơn | I11: =IF(ISBLANK(Merge24!T5), IF(ISBLANK(Merge24!U5), "", Merge24!U5),Merge24!T5& IF(ISBLANK(Merge24!U5), "", "-"&Merge24!U5)) -> 001180056849 | J11: =IF(ISBLANK(Merge24!S5),"",Merge24!S5) -> Giáo viên trung học cơ sở hạng III - V.07.04.32 | K11: 5.5
A12: 5 | B12: 465 | C12: Phạm Thị Hà | D12: PHAM THI HA | E12: 1975 | F12: THCS | G12: THCS Tiên Dược | H12: Sóc Sơn | I12: =IF(ISBLANK(Merge24!T6), IF(ISBLANK(Merge24!U6), "", Merge24!U6),Merge24!T6& IF(ISBLANK(Merge24!U6), "", "-"&Merge24!U6)) -> 001186019155 | J12: =IF(ISBLANK(Merge24!S6),"",Merge24!S6) -> Giáo viên trung học phổ thông hạng III - V.07.05.15 | K12: 5.5
A13: 6 | B13: 466 | C13: Trần Thị Phương Thảo | D13: TRAN THI PHUONG THAO | E13: 1988 | F13: THCS | G13: THCS Thị trấn Sóc Sơn | H13: Sóc Sơn | I13: =IF(ISBLANK(Merge24!T7), IF(ISBLANK(Merge24!U7), "", Merge24!U7),Merge24!T7& IF(ISBLANK(Merge24!U7), "", "-"&Merge24!U7)) -> 001184057507 | J13: =IF(ISBLANK(Merge24!S7),"",Merge24!S7) -> Giáo viên trung học cơ sở hạng II - V.07.04.31 | K13: 5.5
A14: 7 | B14: 467 | C14: Võ Thị Thu Hương | D14: VO THI THU HUONG | E14: 1978 | F14: THPT | G14: THPT Đoàn Kết | H14: Bạch Mai | I14: =IF(ISBLANK(Merge24!T8), IF(ISBLANK(Merge24!U8), "", Merge24!U8),Merge24!T8& IF(ISBLANK(Merge24!U8), "", "-"&Merge24!U8)) -> 019177000235 | J14: =IF(ISBLANK(Merge24!S8),"",Merge24!S8) -> Giáo viên trung học cơ sở hạng II - V.07.04.31 | K14: 6
A15: 8 | B15: 468 | C15: Lê Thị Lý Hải | D15: LE THI LY HAI | E15: 1979 | F15: TH | G15: TH Nam Hồng | H15: Phúc Thịnh | I15: =IF(ISBLANK(Merge24!T9), IF(ISBLANK(Merge24!U9), "", Merge24!U9),Merge24!T9& IF(ISBLANK(Merge24!U9), "", "-"&Merge24!U9)) -> 001192033920 | J15: =IF(ISBLANK(Merge24!S9),"",Merge24!S9) -> Giáo viên tiểu học hạng III – V.07.03.29 | K15: 6
A16: 9 | B16: 469 | C16: Nguyễn Hoài Linh | D16: NGUYEN HOAI LINH | E16: 1992 | F16: THCS | G16: THCS Uy Nỗ | H16: Đông Anh | I16: =IF(ISBLANK(Merge24!T10), IF(ISBLANK(Merge24!U10), "", Merge24!U10),Merge24!T10& IF(ISBLANK(Merge24!U10), "", "-"&Merge24!U10)) -> 001179005747 | J16: =IF(ISBLANK(Merge24!S10),"",Merge24!S10) -> Giáo viên trung học cơ sở hạng II - V.07.04.31 | K16: 6
A17: 10 | B17: 470 | C17: Đặng Thị Mai Phương | D17: DANG THI MAI PHUONG | E17: 1984 | F17: THCS | G17: THCS Ngô Quyền | H17: Đông Anh | I17: =IF(ISBLANK(Merge24!T11), IF(ISBLANK(Merge24!U11), "", Merge24!U11),Merge24!T11& IF(ISBLANK(Merge24!U11), "", "-"&Merge24!U11)) -> ‘001179007111 | J17: =IF(ISBLANK(Merge24!S11),"",Merge24!S11) -> Giáo viên tiểu học hạng II – V.07.03.28 | K17: 6
A18: 11 | B18: 471 | C18: Phạm Thị Lành | D18: PHAM THI LANH | E18: 1982 | F18: THCS | G18: THCS Bắc Hồng | H18: Phúc Thịnh | I18: =IF(ISBLANK(Merge24!T12), IF(ISBLANK(Merge24!U12), "", Merge24!U12),Merge24!T12& IF(ISBLANK(Merge24!U12), "", "-"&Merge24!U12)) -> 001179014240 | J18: =IF(ISBLANK(Merge24!S12),"",Merge24!S12) -> Giáo viên trung học phổ thông hạng III - V.07.05.15 | K18: 6
A19: 12 | B19: 472 | C19: Phan Thị Thu Phương | D19: PHAN THI THU PHUONG | E19: 1980 | F19: THCS | G19: THCS Đông Hội | H19: Đông Anh | I19: =IF(ISBLANK(Merge24!T13), IF(ISBLANK(Merge24!U13), "", Merge24!U13),Merge24!T13& IF(ISBLANK(Merge24!U13), "", "-"&Merge24!U13)) -> 001192049535 | J19: =IF(ISBLANK(Merge24!S13),"",Merge24!S13) -> Giáo viên trung học cơ sở hạng III - V.07.04.32 | K19: 6
A20: 13 | B20: 473 | C20: Nguyễn Thị Thu Hương | D20: NGUYEN THI THU HUONG | E20: 1979 | F20: THCS | G20: THCS Nguyễn Huy Tưởng | H20: Đông Anh | I20: =IF(ISBLANK(Merge24!T14), IF(ISBLANK(Merge24!U14), "", Merge24!U14),Merge24!T14& IF(ISBLANK(Merge24!U14), "", "-"&Merge24!U14)) -> 044188000007 | J20: =IF(ISBLANK(Merge24!S14),"",Merge24!S14) -> Giáo viên trung học cơ sở hạng III - V.07.04.32 | K20: 6
A21: 14 | B21: 474 | C21: Nhữ Thị Toàn Năng | D21: NHU THI TOAN NANG | E21: 1977 | F21: THCS | G21: THCS Hải Bối | H21: Vĩnh Thanh | I21: 1177009345 | J21: Giáo viên trung học cơ sở hạng II - V.07.04.31 | K21: 6
A22: 15 | B22: 475 | C22: Lê Thị Thúy Hà | D22: LE THI THUY HA | E22: 1979 | F22: THPT | G22: THPT Liên Hà | H22: Thư Lâm | I22: 1179014240 | J22: Giáo viên trung học phổ thông hạng III - V.07.05.15 | K22: 5.5
A23: 16 | B23: 476 | C23: Bùi Thanh Thủy | D23: BUI THANH THUY | E23: 1978 | F23: THPT | G23: THPT Nguyễn Gia Thiều | H23: Bồ Đề | I23: =IF(ISBLANK(Merge24!T17), IF(ISBLANK(Merge24!U17), "", Merge24!U17),Merge24!T17& IF(ISBLANK(Merge24!U17), "", "-"&Merge24!U17)) | J23: =IF(ISBLANK(Merge24!S17),"",Merge24!S17) | K23: 6
A24: 17 | B24: 477 | C24: Nguyễn Thị Hằng | D24: NGUYEN THI HANG | E24: 1982 | F24: THPT | G24: THPT Đông Anh | H24: Thư Lâm | I24: 1182033283 | J24: Giáo viên trung học phổ thông hạng II - V.07.05.14 | K24: 6
A25: 18 | B25: 478 | C25: Nguyễn Thị Phương Anh | D25: NGUYEN THI PHUONG ANH | E25: 1978 | F25: THPT | G25: THPT Đông Anh | H25: Thư Lâm | I25: 1178003953 | J25: Giáo viên trung học phổ thông hạng III - V.07.05.15 | K25: 6
A26: 19 | B26: 479 | C26: Đinh Thị Hoa | D26: DINH THI HOA | E26: 1992 | F26: TH | G26: TH Tiền Phong A | H26: Mê Linh | I26: 1192033920 | J26: Giáo viên tiểu học hạng III – V.07.03.29 | K26: 6
A27: 20 | B27: 480 | C27: Nguyễn Thị Quỳnh Thu | D27: NGUYEN THI QUYNH THU | E27: 1986 | F27: THPT | G27: THPT Vân Nội | H27: Phúc Thịnh | I27: 1186019155 | J27: Giáo viên trung học phổ thông hạng III - V.07.05.15 | K27: 6
F28: SỞ GIÁO DỤC & ĐÀO TẠO HÀ NỘI | N28: ĐẠI DIỆN ĐƠN VỊ ĐÀO TẠO
A29: Số học viên đã thi và được cấp chứng chỉ:
A30: Số học viên đạt kết quả đầu ra:
A31: Số học viên không đạt kết quả đầu ra:
A32: Số học viên thuộc diện bất khả kháng
A33: Số học viên được thanh toán:

Sheet Summary
A1: DANH SÁCH THI VÀ KẾT QUẢ IELTS ĐẦU RA
A2: DĐơn vị đào tạo: Công ty CP Trung tâm Anh ngữ AMA Vinh
A4: TT | B4: Mã HV | C4: Họ và tên đệm | D4: Tên | E4: Ngày tháng năm | F4: Bậc dạy | G4: Đơn vị công tác | H4: Quận Huyện | I4: Số CCCD/Hộ chiếu | J4: MÃ ngạch viên chức | K4: Mã lớp | L4: GV đào tạo | R4: CC | S4: NXC | T4: STB | U4: CCT
M5: Nghe | N5: Nói | O5: Đọc | P5: Viết | Q5: Overall
B6: =Total!B1 -> 341 | C6: =Total!C1 -> Trần Thị Thu Hiền | E6: =Total!E1 -> 1977 | F6: =Total!F1 -> THPT | G6: =Total!G1 -> Tam Đồng | H6: =Total!H1 -> Phúc Thịnh | I6: =Total!I1 -> 1177043501 | J6: =Total!J1 -> Giáo viên trung học cơ sở hạng II - V.07.04.31
B7: =Total!B2 -> 342 | C7: =Total!C2 -> Nguyễn Thị Thảo | E7: =Total!E2 -> 1976 | F7: =Total!F2 -> THCS | G7: =Total!G2 -> THCS Tam Đồng | H7: =Total!H2 -> Tiến Thắng | I7: =Total!I2 -> 001176040670 | J7: =Total!J2 -> Giáo viên trung học cơ sở hạng II - V.07.04.31
B8: =Total!B3 -> 343 | C8: =Total!C3 -> Bui Mai Lan | E8: =Total!E3 -> 1977 | F8: =Total!F3 -> THCS | G8: =Total!G3 -> THCS Tiến Thắng | H8: =Total!H3 -> Tiến Thắng | I8: =Total!I3 -> 025177005125 | J8: =Total!J3 -> V07.04.11
B9: =Total!B4 -> 344 | C9: =Total!C4 -> Vũ Hùng Quang | E9: =Total!E4 -> 1975 | F9: =Total!F4 -> THCS | G9: =Total!G4 -> THCS Tráng Việt | H9: =Total!H4 -> Mê Linh | I9: =Total!I4 -> 001075011375 | J9: =Total!J4 -> Giáo viên trung học cơ sở hạng II - V.07.04.31
B10: =Total!B5 -> 345 | C10: =Total!C5 -> Phùng Thị Kim Thao | E10: =Total!E5 -> 1977 | F10: =Total!F5 -> THCS | G10: =Total!G5 -> THCS Phạm Hồng Thái | H10: =Total!H5 -> Mê Linh | I10: =Total!I5 -> 001177009537 | J10: =Total!J5 -> Giáo viên trung học cơ sở hạng III - V.07.04.32
B11: =Total!B6 -> 4 | C11: =Total!C6 -> Trần Thị Thanh Tâm | E11: =Total!E6 -> 1983 | F11: =Total!F6 -> TH | G11: =Total!G6 -> TH Xuân Canh | H11: =Total!H6 -> Đông Anh | I11: =Total!I6 -> 026183003026-E032337481 | J11: =Total!J6 -> Giáo viên tiểu học hạng II – V.07.03.28
B12: =Total!B7 -> 347 | C12: =Total!C7 -> Ngô Thị Hồng Dương | E12: =Total!E7 -> 1975 | F12: =Total!F7 -> THCS | G12: =Total!G7 -> THCS Kim Hoa | H12: =Total!H7 -> Quang Minh | I12: =Total!I7 -> 001175030348 | J12: =Total!J7 -> Giáo viên trung học cơ sở hạng II - V.07.04.31
B13: =Total!B8 -> 348 | C13: =Total!C8 -> Ngô Thị Thanh Thuỷ | E13: =Total!E8 -> 1977 | F13: =Total!F8 -> TH | G13: =Total!G8 -> TH Kim Hoa A | H13: =Total!H8 -> Quang Minh | I13: =Total!I8 -> 001177032960 | J13: =Total!J8 -> Giáo viên tiểu học hạng II – V.07.03.28
B14: =Total!B9 -> 349 | C14: =Total!C9 -> Nguyễn Thị Yến | E14: =Total!E9 -> 1975 | F14: =Total!F9 -> THCS | G14: =Total!G9 -> THCS Hồng Kỳ | H14: =Total!H9 -> Trung Giã | I14: =Total!I9 -> 001175014156 | J14: =Total!J9 -> Giáo viên trung học cơ sở hạng II - V.07.04.31
B15: =Total!B10 -> 350 | C15: =Total!C10 -> Nguyễn Thị Hồng Vân | E15: =Total!E10 -> 1976 | F15: =Total!F10 -> THCS | G15: =Total!G10 -> THCS Trung Giã | H15: =Total!H10 -> Trung Giã | I15: =Total!I10 -> 001176048717 | J15: =Total!J10 -> Giáo viên trung học cơ sở hạng III - V.07.04.32
B16: =Total!B11 -> 351 | C16: =Total!C11 -> Nguyễn Thị Mai | E16: =Total!E11 -> 1975 | F16: =Total!F11 -> THCS | G16: =Total!G11 -> THCS Nguyễn Du | H16: =Total!H11 -> Sóc Sơn | I16: =Total!I11 -> 0 | J16: =Total!J11 -> 0
B17: =Total!B12 -> 352 | C17: =Total!C12 -> Vương Thị Hạnh | E17: =Total!E12 -> 1984 | F17: =Total!F12 -> THCS | G17: =Total!G12 -> THCS Tân Minh A | H17: =Total!H12 -> Sóc Sơn | I17: =Total!I12 -> 1184022018 | J17: =Total!J12 -> Giáo viên trung học cơ sở hạng III - V.07.04.32
... B145: =Total!B140 -> 480 | C145: =Total!C140 -> Nguyễn Thị Quỳnh Thu | E145: =Total!E140 -> 1986 | F145: =Total!F140 -> THPT | G145: =Total!G140 -> THPT Vân Nội | H145: =Total!H140 -> Phúc Thịnh | I145: =Total!I140 -> 1186019155 | J145: =Total!J140 -> Giáo viên trung học phổ thông hạng III - V.07.05.15

Sheet Total
A1: 1 | B1: 341 | C1: Trần Thị Thu Hiền | D1: TRAN THI THU HIEN | E1: 1977 | F1: THPT | G1: Tam Đồng | H1: Phúc Thịnh | I1: 1177043501 | J1: Giáo viên trung học cơ sở hạng II - V.07.04.31
A2: 2 | B2: 342 | C2: Nguyễn Thị Thảo | D2: NGUYEN THI THAO | E2: 1976 | F2: THCS | G2: THCS Tam Đồng | H2: Tiến Thắng | I2: 001176040670 | J2: Giáo viên trung học cơ sở hạng II - V.07.04.31
A3: 3 | B3: 343 | C3: Bui Mai Lan | D3: BUI MAI LAN | E3: 1977 | F3: THCS | G3: THCS Tiến Thắng | H3: Tiến Thắng | I3: 025177005125 | J3: V07.04.11
A4: 4 | B4: 344 | C4: Vũ Hùng Quang | D4: VU HUNG QUANG | E4: 1975 | F4: THCS | G4: THCS Tráng Việt | H4: Mê Linh | I4: 001075011375 | J4: Giáo viên trung học cơ sở hạng II - V.07.04.31
A5: 5 | B5: 345 | C5: Phùng Thị Kim Thao | D5: PHUNG THI KIM THAO | E5: 1977 | F5: THCS | G5: THCS Phạm Hồng Thái | H5: Mê Linh | I5: 001177009537 | J5: Giáo viên trung học cơ sở hạng III - V.07.04.32
A6: 6 | B6: 4 | C6: Trần Thị Thanh Tâm | D6: TRAN THI THANH TAM | E6: 1983 | F6: TH | G6: TH Xuân Canh | H6: Đông Anh | I6: 026183003026-E032337481 | J6: Giáo viên tiểu học hạng II – V.07.03.28
A7: 7 | B7: 347 | C7: Ngô Thị Hồng Dương | D7: NGO THI HONG DUONG | E7: 1975 | F7: THCS | G7: THCS Kim Hoa | H7: Quang Minh | I7: 001175030348 | J7: Giáo viên trung học cơ sở hạng II - V.07.04.31
A8: 8 | B8: 348 | C8: Ngô Thị Thanh Thuỷ | D8: NGO THI THANH THUY | E8: 1977 | F8: TH | G8: TH Kim Hoa A | H8: Quang Minh | I8: 001177032960 | J8: Giáo viên tiểu học hạng II – V.07.03.28
A9: 9 | B9: 349 | C9: Nguyễn Thị Yến | D9: NGUYEN THI YEN | E9: 1975 | F9: THCS | G9: THCS Hồng Kỳ | H9: Trung Giã | I9: 001175014156 | J9: Giáo viên trung học cơ sở hạng II - V.07.04.31
A10: 10 | B10: 350 | C10: Nguyễn Thị Hồng Vân | D10: NGUYEN THI HONG VAN | E10: 1976 | F10: THCS | G10: THCS Trung Giã | H10: Trung Giã | I10: 001176048717 | J10: Giáo viên trung học cơ sở hạng III - V.07.04.32
A11: 11 | B11: 351 | C11: Nguyễn Thị Mai | D11: NGUYEN THI MAI | E11: 1975 | F11: THCS | G11: THCS Nguyễn Du | H11: Sóc Sơn
A12: 12 | B12: 352 | C12: Vương Thị Hạnh | D12: VUONG THI HANH | E12: 1984 | F12: THCS | G12: THCS Tân Minh A | H12: Sóc Sơn | I12: 1184022018 | J12: Giáo viên trung học cơ sở hạng III - V.07.04.32
A13: 13 | B13: 353 | C13: Trịnh Thị Lê Hằng | D13: TRINH THI LE HANG | E13: 1976 | F13: THCS | G13: THCS Tân Minh A | H13: Sóc Sơn | I13: 001184022018 | J13: Giáo viên trung học cơ sở hạng III - V.07.04.32
A14: 14 | B14: 354 | C14: Lê Đức Vĩnh | D14: LE DUC VINH | E14: 1974 | F14: THCS | G14: THCS Phù Linh | H14: Sóc Sơn | I14: 1074022571 | J14: Giáo viên trung học cơ sở hạng II - V.07.04.31
A15: 15 | B15: 355 | C15: Lê Thị Duyên | D15: LE THI DUYEN | E15: 1984 | F15: TH | G15: TH Đào Duy Tùng | H15: Đông Anh | I15: 1184030240 | J15: Giáo viên tiểu học hạng III – V.07.03.29
A16: 16 | B16: 356 | C16: Vương Phương Lâm | D16: VUONG PHUONG LAM | E16: 1980 | F16: TH | G16: TH Đại Mạch | H16: Thiên Lộc | I16: 1180014694 | J16: Giáo viên tiểu học hạng III – V.07.03.29
A17: 17 | B17: 357 | C17: Vũ Thị Mẫn | D17: VU THI MAN | E17: 1980 | F17: TH | G17: TH Lê Hữu Tựu | H17: Phúc Thịnh | I17: 1180005662 | J17: Giáo viên tiểu học hạng III – V.07.03.29
A18: 18 | B18: 358 | C18: Nguyễn Thị Bích Loan | D18: NGUYEN THI BICH LOAN | E18: 1977 | F18: TH | G18: TH Hải Bối | H18: Vĩnh Thanh | I18: 001180005662 | J18: Giáo viên tiểu học hạng III – V.07.03.29
A19: 19 | B19: 359 | C19: Nguyễn Tư Vinh | D19: NGUYEN TU VINH | E19: 1977 | F19: THCS | G19: THCS Liên Hà | H19: Thư Lâm | I19: 27177000344 | J19: Giáo viên trung học cơ sở hạng II - V.07.04.31
A20: 20 | B20: 360 | C20: Dương Thị Thanh Hương | D20: DUONG THI THANH HUONG | E20: 1976 | F20: THCS | G20: THCS Liên Hà | H20: Thư Lâm | I20: 1176045858 | J20: Giáo viên trung học cơ sở hạng II - V.07.04.31
A21: 1 | B21: 361 | C21: Phạm Thị Cửu | D21: PHAM THI CUU | E21: 1976 | F21: THCS | G21: THCS Xuân Nộn | H21: Thư Lâm | I21: 001176046134 | J21: Giáo viên trung học cơ sở hạng II - V.07.04.31
A22: 2 | B22: 362 | C22: Hoàng Thu Hằng | D22: HOANG THU HANG | E22: 1975 | F22: THCS | G22: THCS Uy Nỗ | H22: Đông Anh | I22: 001178029456 | J22: Giáo viên trung học phổ thông hạng III - V.07.05.15
A23: 3 | B23: 363 | C23: Ngô Thị Hà | D23: NGO THI HA | E23: 1975 | F23: THCS | G23: THCS Vân Hà | H23: Thư Lâm | I23: 035185004411 | J23: Giáo viên trung học phổ thông hạng II - V.07.05.14
A24: 4 | B24: 364 | C24: Nghiêm Thị Nụ | D24: NGHIEM THI NU | E24: 1984 | F24: THPT | G24: THPT Liên Hà | H24: Thư Lâm | I24: 034178005875 | J24: Giáo viên tiểu học hạng II – V.07.03.28
A25: 5 | B25: 365 | C25: Phạm Thị Thu Thiêm | D25: PHAM THI THU THIEM | E25: 1976 | F25: THPT | G25: THPT Liên Hà | H25: Thư Lâm | I25: 001181004093 | J25: Giáo viên tiểu học hạng II – V.07.03.28
A26: 6 | B26: 366 | C26: Nguyễn Thị Nhung | D26: NGUYEN THI NHUNG | E26: 1978 | F26: THPT | G26: THPT Đông Anh | H26: Thư Lâm | I26: 001178029862 | J26: Giáo viên trung học cơ sở hạng II - V.07.04.31
A27: 7 | B27: 367 | C27: Nguyễn Thế Huệ | D27: NGUYEN THE HUE | E27: 1977 | F27: THPT | G27: THPT Đông Anh | H27: Thư Lâm | I27: 001077040753 | J27: Giáo viên trung học phổ thông hạng III - V.07.05.15
A28: 8 | B28: 368 | C28: Nguyễn Thị Nga | D28: NGUYEN THI NGA | E28: 1985 | F28: THPT | G28: THPT Tiến Thịnh | H28: Yên Lãng | I28: 35185004411 | J28: Giáo viên trung học phổ thông hạng II - V.07.05.14
A29: 9 | B29: 369 | C29: Phùng Thu Hường | D29: PHUNG THU HUONG | E29: 1987 | F29: TH | G29: TH Tự Lập B | H29: Tiến Thắng | I29: 001085037860 | J29: Giáo viên tiểu học hạng IV - V.07.03.09
A30: 10 | B30: 370 | C30: Đoàn Phương Thảo | D30: DOAN PHUONG THAO | E30: 1983 | F30: TH | G30: TH Thanh Lâm B | H30: Quang Minh | I30: 024182000152 | J30: Giáo viên trung học phổ thông hạng III - V.07.05.15
A31: 11 | B31: 371 | C31: Nguyễn Thanh Hà | D31: NGUYEN THANH HA | E31: 1984 | F31: TH | G31: TH Chu Phan | H31: Yên Lãng | I31: 001176046317 | J31: Giáo viên trung học phổ thông hạng III - V.07.05.15
A32: 12 | B32: 372 | C32: Nguyễn Hoài Thanh | D32: NGUYEN HOAI THANH | E32: 1978 | F32: TH | G32: TH Đại Thịnh B | H32: Quang Minh | I32: 001187032876 | J32: Giáo viên tiểu học hạng III – V.07.03.29
A33: 13 | B33: 373 | C33: Nguyễn Văn Bằng | D33: NGUYEN VAN BANG | E33: 1985 | F33: TH | G33: TH Tự Lập A | H33: Tiến Thắng | I33: 001184017736 | J33: Giáo viên trung học phổ thông hạng III - V.07.05.15
A34: 14 | B34: 374 | C34: Lê Thị Loan | D34: LE THI LOAN | E34: 1981 | F34: TH | G34: TH Thạch Đà B | H34: Yên Lãng | I34: 1181004093 | J34: Giáo viên tiểu học hạng II – V.07.03.28
A35: 15 | B35: 375 | C35: Nguyễn Thị Hằng | D35: NGUYEN THI HANG | E35: 1982 | F35: TH | G35: TH Mê Linh | H35: Mê Linh | I35: 987892839 | J35: Giáo viên tiểu học hạng III - V07.03.08
A36: 16 | B36: 376 | C36: Lê Thị Hạnh | D36: LE THI HANH | E36: 1978 | F36: THCS | G36: THCS Tráng Việt | H36: Mê Linh | I36: 1178029862 | J36: Giáo viên trung học cơ sở hạng II - V.07.04.31
A37: 17 | B37: 377 | C37: Nguyễn Thị Thắm | D37: NGUYEN THI THAM | E37: 1978 | F37: THCS | G37: THCS Tiền Phong | H37: Mê Linh | I37: 1178010346 | J37: Giáo viên trung học cơ sở hạng II - V.07.04.31
A38: 18 | B38: 378 | C38: Nguyễn Thu Hường | D38: NGUYEN THU HUONG | E38: 1982 | F38: THCS | G38: THCS Văn Khê | H38: Mê Linh | I38: 26182001327 | J38: Giáo viên trung học cơ sở hạng II - V.07.04.31
